Workbook

Sheet Dashboard
A1: DASHBOARD DE VENDAS - DISTRIBUIÇÃO DE VENTILADORES
B4: FATURAMENTO TOTAL | E4: TOTAL UNIDADES VENDIDAS | H4: LUCRO LÍQUIDO TOTAL
B5: =SUM('Dados de Vendas'!H2:H151) -> 237179.7 | E5: =SUM('Dados de Vendas'!G2:G151) -> 1203 | H5: =SUM('Dados de Vendas'!J2:J151) -> 124146.7
B8: Faturamento por Canal | E8: Faturamento por Região
B9: Canal | C9: Faturamento | E9: Região | F9: Faturamento
B10: E-commerce | C10: =SUMIF('Dados de Vendas'!C$2:C$151, B10, 'Dados de Vendas'!H$2:H$151) -> 40527.3 | E10: Sudeste | F10: =SUMIF('Dados de Vendas'!D$2:D$151, E10, 'Dados de Vendas'!H$2:H$151) -> 33430.1
B11: Lojas Físicas | C11: =SUMIF('Dados de Vendas'!C$2:C$151, B11, 'Dados de Vendas'!H$2:H$151) -> 65317.4 | E11: Nordeste | F11: =SUMIF('Dados de Vendas'!D$2:D$151, E11, 'Dados de Vendas'!H$2:H$151) -> 43828
B12: Marketplace | C12: =SUMIF('Dados de Vendas'!C$2:C$151, B12, 'Dados de Vendas'!H$2:H$151) -> 81059.2 | E12: Sul | F12: =SUMIF('Dados de Vendas'!D$2:D$151, E12, 'Dados de Vendas'!H$2:H$151) -> 36482.4
B13: Televendas | C13: =SUMIF('Dados de Vendas'!C$2:C$151, B13, 'Dados de Vendas'!H$2:H$151) -> 50275.8 | E13: Centro-Oeste | F13: =SUMIF('Dados de Vendas'!D$2:D$151, E13, 'Dados de Vendas'!H$2:H$151) -> 56570.8
B14: Total | C14: =SUM(C10:C13) -> 237179.7 | E14: Norte | F14: =SUMIF('Dados de Vendas'!D$2:D$151, E14, 'Dados de Vendas'!H$2:H$151) -> 66868.4
E15: Total | F15: =SUM(F10:F14) -> 237179.7

Sheet Dados de Vendas
A1: IDPedido | B1: Data | C1: Canal de Venda | D1: Região | E1: Modelo de Ventilador | F1: Preço Unitário | G1: Quantidade | H1: Faturamento | I1: Custo do Produto | J1: Margem Lucro
A2: REQ0002 | B2: 45985 | C2: E-commerce | D2: Sudeste | E2: Ventilador de Teto Moderno | F2: 349.9 | G2: 4 | H2: =F2*G2 -> 1399.6 | I2: =165*G2 -> 660 | J2: =H2-I2 -> 739.6
A3: REQ0003 | B3: 45772 | C3: Lojas Físicas | D3: Sudeste | E3: Mini Ventilador USB | F3: 49.9 | G3: 2 | H3: =F3*G3 -> 99.8 | I3: =18*G3 -> 36 | J3: =H3-I3 -> 63.8
A4: REQ0004 | B4: 45960 | C4: Televendas | D4: Sudeste | E4: Ventilador de Mesa 30cm | F4: 149.9 | G4: 2 | H4: =F4*G4 -> 299.8 | I4: =75*G4 -> 150 | J4: =H4-I4 -> 149.8
A5: REQ0005 | B5: 45769 | C5: Lojas Físicas | D5: Norte | E5: Mini Ventilador USB | F5: 49.9 | G5: 1 | H5: =F5*G5 -> 49.9 | I5: =18*G5 -> 18 | J5: =H5-I5 -> 31.9
A6: REQ0006 | B6: 45945 | C6: Lojas Físicas | D6: Norte | E6: Circulador de Ar Turbo | F6: 249.9 | G6: 4 | H6: =F6*G6 -> 999.6 | I6: =120*G6 -> 480 | J6: =H6-I6 -> 519.6
A7: REQ0007 | B7: 45887 | C7: Marketplace | D7: Sudeste | E7: Ventilador de Coluna 40cm | F7: 199.9 | G7: 12 | H7: =F7*G7 -> 2398.8 | I7: =98*G7 -> 1176 | J7: =H7-I7 -> 1222.8
A8: REQ0008 | B8: 45874 | C8: Marketplace | D8: Sul | E8: Ventilador de Coluna 40cm | F8: 199.9 | G8: 4 | H8: =F8*G8 -> 799.6 | I8: =98*G8 -> 392 | J8: =H8-I8 -> 407.6
A9: REQ0009 | B9: 45830 | C9: E-commerce | D9: Sudeste | E9: Circulador de Ar Turbo | F9: 249.9 | G9: 2 | H9: =F9*G9 -> 499.8 | I9: =120*G9 -> 240 | J9: =H9-I9 -> 259.8
A10: REQ0010 | B10: 45841 | C10: Marketplace | D10: Norte | E10: Ventilador de Teto Moderno | F10: 349.9 | G10: 13 | H10: =F10*G10 -> 4548.7 | I10: =165*G10 -> 2145 | J10: =H10-I10 -> 2403.7
A11: REQ0011 | B11: 45680 | C11: Televendas | D11: Norte | E11: Ventilador de Mesa 30cm | F11: 149.9 | G11: 15 | H11: =F11*G11 -> 2248.5 | I11: =75*G11 -> 1125 | J11: =H11-I11 -> 1123.5
A12: REQ0012 | B12: 45851 | C12: E-commerce | D12: Norte | E12: Ventilador de Teto Moderno | F12: 349.9 | G12: 14 | H12: =F12*G12 -> 4898.6 | I12: =165*G12 -> 2310 | J12: =H12-I12 -> 2588.6
A13: REQ0013 | B13: 45979 | C13: Marketplace | D13: Norte | E13: Ventilador de Coluna 40cm | F13: 199.9 | G13: 12 | H13: =F13*G13 -> 2398.8 | I13: =98*G13 -> 1176 | J13: =H13-I13 -> 1222.8
A14: REQ0014 | B14: 45693 | C14: E-commerce | D14: Nordeste | E14: Ventilador de Teto Moderno | F14: 349.9 | G14: 2 | H14: =F14*G14 -> 699.8 | I14: =165*G14 -> 330 | J14: =H14-I14 -> 369.8
A15: REQ0015 | B15: 45777 | C15: E-commerce | D15: Centro-Oeste | E15: Ventilador de Teto Moderno | F15: 349.9 | G15: 8 | H15: =F15*G15 -> 2799.2 | I15: =165*G15 -> 1320 | J15: =H15-I15 -> 1479.2
A16: REQ0016 | B16: 45983 | C16: Marketplace | D16: Nordeste | E16: Ventilador de Teto Moderno | F16: 349.9 | G16: 6 | H16: =F16*G16 -> 2099.4 | I16: =165*G16 -> 990 | J16: =H16-I16 -> 1109.4
A17: REQ0017 | B17: 45765 | C17: Marketplace | D17: Sudeste | E17: Mini Ventilador USB | F17: 49.9 | G17: 11 | H17: =F17*G17 -> 548.9 | I17: =18*G17 -> 198 | J17: =H17-I17 -> 350.9
A18: REQ0018 | B18: 45745 | C18: Lojas Físicas | D18: Nordeste | E18: Circulador de Ar Turbo | F18: 249.9 | G18: 7 | H18: =F18*G18 -> 1749.3 | I18: =120*G18 -> 840 | J18: =H18-I18 -> 909.3
A19: REQ0019 | B19: 45796 | C19: Lojas Físicas | D19: Sul | E19: Ventilador de Mesa 30cm | F19: 149.9 | G19: 4 | H19: =F19*G19 -> 599.6 | I19: =75*G19 -> 300 | J19: =H19-I19 -> 299.6
A20: REQ0020 | B20: 45674 | C20: Marketplace | D20: Centro-Oeste | E20: Ventilador de Teto Moderno | F20: 349.9 | G20: 2 | H20: =F20*G20 -> 699.8 | I20: =165*G20 -> 330 | J20: =H20-I20 -> 369.8
A21: REQ0021 | B21: 45766 | C21: Marketplace | D21: Nordeste | E21: Circulador de Ar Turbo | F21: 249.9 | G21: 7 | H21: =F21*G21 -> 1749.3 | I21: =120*G21 -> 840 | J21: =H21-I21 -> 909.3
A22: REQ0022 | B22: 45987 | C22: Televendas | D22: Nordeste | E22: Ventilador de Teto Moderno | F22: 349.9 | G22: 3 | H22: =F22*G22 -> 1049.7 | I22: =165*G22 -> 495 | J22: =H22-I22 -> 554.7
A23: REQ0023 | B23: 45784 | C23: Marketplace | D23: Norte | E23: Circulador de Ar Turbo | F23: 249.9 | G23: 15 | H23: =F23*G23 -> 3748.5 | I23: =120*G23 -> 1800 | J23: =H23-I23 -> 1948.5
A24: REQ0024 | B24: 45956 | C24: Televendas | D24: Sul | E24: Ventilador de Coluna 40cm | F24: 199.9 | G24: 3 | H24: =F24*G24 -> 599.7 | I24: =98*G24 -> 294 | J24: =H24-I24 -> 305.7
A25: REQ0025 | B25: 45918 | C25: Televendas | D25: Sudeste | E25: Ventilador de Mesa 30cm | F25: 149.9 | G25: 14 | H25: =F25*G25 -> 2098.6 | I25: =75*G25 -> 1050 | J25: =H25-I25 -> 1048.6
A26: REQ0026 | B26: 45714 | C26: Lojas Físicas | D26: Nordeste | E26: Circulador de Ar Turbo | F26: 249.9 | G26: 10 | H26: =F26*G26 -> 2499 | I26: =120*G26 -> 1200 | J26: =H26-I26 -> 1299
A27: REQ0027 | B27: 45690 | C27: Televendas | D27: Centro-Oeste | E27: Mini Ventilador USB | F27: 49.9 | G27: 8 | H27: =F27*G27 -> 399.2 | I27: =18*G27 -> 144 | J27: =H27-I27 -> 255.2
A28: REQ0028 | B28: 45928 | C28: Marketplace | D28: Norte | E28: Ventilador de Mesa 30cm | F28: 149.9 | G28: 11 | H28: =F28*G28 -> 1648.9 | I28: =75*G28 -> 825 | J28: =H28-I28 -> 823.9
A29: REQ0029 | B29: 45716 | C29: Marketplace | D29: Sul | E29: Ventilador de Mesa 30cm | F29: 149.9 | G29: 5 | H29: =F29*G29 -> 749.5 | I29: =75*G29 -> 375 | J29: =H29-I29 -> 374.5
A30: REQ0030 | B30: 45880 | C30: Lojas Físicas | D30: Centro-Oeste | E30: Ventilador de Mesa 30cm | F30: 149.9 | G30: 12 | H30: =F30*G30 -> 1798.8 | I30: =75*G30 -> 900 | J30: =H30-I30 -> 898.8
A31: REQ0031 | B31: 45792 | C31: Lojas Físicas | D31: Norte | E31: Ventilador de Mesa 30cm | F31: 149.9 | G31: 14 | H31: =F31*G31 -> 2098.6 | I31: =75*G31 -> 1050 | J31: =H31-I31 -> 1048.6
A32: REQ0032 | B32: 45978 | C32: Marketplace | D32: Norte | E32: Mini Ventilador USB | F32: 49.9 | G32: 4 | H32: =F32*G32 -> 199.6 | I32: =18*G32 -> 72 | J32: =H32-I32 -> 127.6
A33: REQ0033 | B33: 45736 | C33: Marketplace | D33: Nordeste | E33: Mini Ventilador USB | F33: 49.9 | G33: 13 | H33: =F33*G33 -> 648.7 | I33: =18*G33 -> 234 | J33: =H33-I33 -> 414.7
A34: REQ0034 | B34: 45929 | C34: E-commerce | D34: Norte | E34: Ventilador de Teto Moderno | F34: 349.9 | G34: 8 | H34: =F34*G34 -> 2799.2 | I34: =165*G34 -> 1320 | J34: =H34-I34 -> 1479.2
A35: REQ0035 | B35: 45667 | C35: E-commerce | D35: Sul | E35: Ventilador de Teto Moderno | F35: 349.9 | G35: 4 | H35: =F35*G35 -> 1399.6 | I35: =165*G35 -> 660 | J35: =H35-I35 -> 739.6
A36: REQ0036 | B36: 45687 | C36: Lojas Físicas | D36: Norte | E36: Ventilador de Mesa 30cm | F36: 149.9 | G36: 2 | H36: =F36*G36 -> 299.8 | I36: =75*G36 -> 150 | J36: =H36-I36 -> 149.8
A37: REQ0037 | B37: 45906 | C37: E-commerce | D37: Norte | E37: Ventilador de Coluna 40cm | F37: 199.9 | G37: 3 | H37: =F37*G37 -> 599.7 | I37: =98*G37 -> 294 | J37: =H37-I37 -> 305.7
A38: REQ0038 | B38: 45995 | C38: Televendas | D38: Norte | E38: Ventilador de Coluna 40cm | F38: 199.9 | G38: 5 | H38: =F38*G38 -> 999.5 | I38: =98*G38 -> 490 | J38: =H38-I38 -> 509.5
A39: REQ0039 | B39: 45928 | C39: Televendas | D39: Nordeste | E39: Mini Ventilador USB | F39: 49.9 | G39: 13 | H39: =F39*G39 -> 648.7 | I39: =18*G39 -> 234 | J39: =H39-I39 -> 414.7
A40: REQ0040 | B40: 46011 | C40: Lojas Físicas | D40: Sul | E40: Circulador de Ar Turbo | F40: 249.9 | G40: 11 | H40: =F40*G40 -> 2748.9 | I40: =120*G40 -> 1320 | J40: =H40-I40 -> 1428.9
...
